Workbook

Sheet Leaderboard
A1: Name | B1: Total | C1: Groups stage | D1: Round of 32 | E1: Round of 16 | F1: Quarter finals | G1: Semi finals | H1: 3rd place | I1: Final | J1: Bonus questions
A2: Elwebo + Gemini | B2: =SUM(C2:J2) -> 147 | C2: =INDIRECT("'"&A2&"'!K31") -> 35 | D2: =INDIRECT("'"&A2&"'!S47") -> 82 | E2: =INDIRECT("'"&A2&"'!S60") -> 30
A3: Emi | B3: =SUM(C3:J3) -> 146 | C3: =INDIRECT("'"&A3&"'!K31") -> 32 | D3: =INDIRECT("'"&A3&"'!S47") -> 78 | E3: =INDIRECT("'"&A3&"'!S60") -> 36
A4: Llucho | B4: =SUM(C4:J4) -> 141 | C4: =INDIRECT("'"&A4&"'!K31") -> 29 | D4: =INDIRECT("'"&A4&"'!S47") -> 76 | E4: =INDIRECT("'"&A4&"'!S60") -> 36
A5: Daniel | B5: =SUM(C5:J5) -> 136 | C5: =INDIRECT("'"&A5&"'!K31") -> 30 | D5: =INDIRECT("'"&A5&"'!S47") -> 76 | E5: =INDIRECT("'"&A5&"'!S60") -> 30
A6: Elwebo con AI-ChatGPT | B6: =SUM(C6:J6) -> 135 | C6: =INDIRECT("'"&A6&"'!K31") -> 27 | D6: =INDIRECT("'"&A6&"'!S47") -> 66 | E6: =INDIRECT("'"&A6&"'!S60") -> 42
A7: Amal | B7: =SUM(C7:J7) -> 134 | C7: =INDIRECT("'"&A7&"'!K31") -> 28 | D7: =INDIRECT("'"&A7&"'!S47") -> 58 | E7: =INDIRECT("'"&A7&"'!S60") -> 48
A8: Elwebo Lavenganza | B8: =SUM(C8:J8) -> 116 | C8: =INDIRECT("'"&A8&"'!K31") -> 28 | D8: =INDIRECT("'"&A8&"'!S47") -> 58 | E8: =INDIRECT("'"&A8&"'!S60") -> 30
A9: paul | B9: =SUM(C9:J9) -> 113 | C9: =INDIRECT("'"&A9&"'!K31") -> 23 | D9: =INDIRECT("'"&A9&"'!S47") -> 60 | E9: =INDIRECT("'"&A9&"'!S60") -> 30
A10: jjpro | B10: =SUM(C10:J10) -> 101 | C10: =INDIRECT("'"&A10&"'!K31") -> 23 | D10: =INDIRECT("'"&A10&"'!S47") -> 66 | E10: =INDIRECT("'"&A10&"'!S60") -> 12
A11: Irina | B11: =SUM(C11:J11) -> 90 | C11: =INDIRECT("'"&A11&"'!K31") -> 18 | D11: =INDIRECT("'"&A11&"'!S47") -> 36 | E11: =INDIRECT("'"&A11&"'!S60") -> 36
A12: NoDorex | B12: =SUM(C12:J12) -> 88 | C12: =INDIRECT("'"&A12&"'!K31") -> 12 | D12: =INDIRECT("'"&A12&"'!S47") -> 40 | E12: =INDIRECT("'"&A12&"'!S60") -> 36

Sheet TemplateResults
A2: Question | C2: Your answer | F2: Points
A3: 1 | B3: Name
A4: 2 | B4: Winner team | F4: 10
A5: 3 | B5: Who wil be runner-up? | F5: 6
A6: 4 | B6: Favorite team (it's ok NOT to choose your own country)
A7: 5 | B7: Haw far will your favorite team go? | F7: 4
A8: 6 | B8: Top scorer | F8: 4
A9: 7 | B9: How far will Ecuador go in the cup? | F9: 4
A11: Groups stage | C11: Group A | E11: Group B | G11: Group C
B12: =D14 -> South Korea | C12: 1 | D12: Mexico | E12: 1 | F12: Switzerland | G12: 1 | H12: Brazil
B13: =F14 -> Bosnia | C13: 2 | D13: South Africa | E13: 2 | F13: Canada | G13: 2 | H13: Morocco
B14: =H14 -> Scotland | C14: 3 | D14: South Korea | E14: 3 | F14: Bosnia | G14: 3 | H14: Scotland
B15: =D18 -> Paraguay | C15: Group D | E15: Group E | G15: Group F
B16: =F18 -> Ecuador | C16: 1 | D16: United States | E16: 1 | F16: Germany | G16: 1 | H16: Netherlands
B17: =H18 -> Sweden | C17: 2 | D17: Australia | E17: 2 | F17: Ivory Coast | G17: 2 | H17: Japan
B18: =D22 -> Iran | C18: 3 | D18: Paraguay | E18: 3 | F18: Ecuador | G18: 3 | H18: Sweden | M18: Round of 32 | Q18: Penalty | S18: Score
B19: =F22 -> Uruguay | C19: Group G | E19: Group H | G19: Group I | M19: Germany | N19: 1 | O19: 1 | P19: Paraguay | Q19: 3 | R19: 4
B20: =H22 -> Senegal | C20: 1 | D20: Belgium | E20: 1 | F20: Spain | G20: 1 | H20: France | M20: France | N20: 3 | O20: 0 | P20: Sweden
B21: =D26 -> Algeria | C21: 2 | D21: Egypt | E21: 2 | F21: Cape Verde | G21: 2 | H21: Norway | M21: South Africa | N21: 0 | O21: 1 | P21: Canada
B22: =F26 -> DR Congo | C22: 3 | D22: Iran | E22: 3 | F22: Uruguay | G22: 3 | H22: Senegal | M22: Nederlands | N22: 1 | O22: 1 | P22: Morroco | Q22: 2 | R22: 3
B23: =H26 -> Ghana | C23: Group J | E23: Group K | G23: Group L | M23: Portugal | N23: 2 | O23: 1 | P23: Croatia
C24: 1 | D24: Argentina | E24: 1 | F24: Colombia | G24: 1 | H24: England | M24: Spain | N24: 3 | O24: 0 | P24: Austria
C25: 2 | D25: Austria | E25: 2 | F25: Portugal | G25: 2 | H25: Croatia | M25: United States | N25: 2 | O25: 0 | P25: Bosnia
C26: 3 | D26: Algeria | E26: 3 | F26: DR Congo | G26: 3 | H26: Ghana | M26: Belgium | N26: 3 | O26: 2 | P26: Senegal
C27: Best 3rd's | M27: Brazil | N27: 2 | O27: 1 | P27: Japan
C28: 1 | D28: DR Congo | E28: 4 | F28: Ecuador | G28: 7 | H28: Paraguay | M28: Ivory Coast | N28: 1 | O28: 2 | P28: Norway
C29: 2 | D29: Sweden | E29: 5 | F29: Bosnia | G29: 8 | H29: Senegal | M29: Mexico | N29: 2 | O29: 0 | P29: Ecuador
C30: 3 | D30: Ghana | E30: 6 | F30: Algeria | M30: England | N30: 2 | O30: 1 | P30: DR Congo
M31: Argentina | N31: 3 | O31: 2 | P31: Cape Verde
J32: R32 | K32: 4 | M32: Australia | N32: 1 | O32: 1 | P32: Egypt | Q32: 2 | R32: 4
J33: R16 | K33: 6 | M33: Switzerland | N33: 2 | O33: 0 | P33: Algeria
J34: QF | K34: 10 | M34: Colombia | N34: 1 | O34: 0 | P34: Ghana
J35: SF | K35: 16
J36: 0.625 | K36: 14 | M36: Bonus questions ( 2 points each )
J37: Final | K37: 20 | M37: How many matches will go to extra time? | Q37: 5 - 8
M38: How many matches will be decided by penalties? | Q38: 0 - 4
M39: Which team will score the most goals? | Q39: Egypt
M40: Total goals scored in the R-32 (no penalties) | Q40: 41 - 50
M41: Which team will score the fastest goal? | Q41: DR Congo
M42: Which team will score the latest goal (including extra time)? | Q42: Belgium
...

Sheet Amal
A2: Question | C2: Your answer | F2: Points
A3: 1 | B3: Name | C3: Amal
A4: 2 | B4: Winner team | C4: Spain | F4: 10
A5: 3 | B5: Who wil be runner-up? | C5: France | F5: 6
A6: 4 | B6: Favorite team (it's ok NOT to choose your own country) | C6: Morocco
A7: 5 | B7: Haw far will your favorite team go? | C7: Quarter final | F7: 4
A8: 6 | B8: Top scorer | C8: Mbappe | F8: 4
A9: 7 | B9: How far will Ecuador go in the cup? | C9: Round of 16 | F9: 4
A11: Groups stage | C11: Group A | E11: Group B | G11: Group C | J11: Group | K11: Your score
B12: =D14 -> Czech Republic | C12: 1 | D12: Mexico | E12: 1 | F12: Switzerland | G12: 1 | H12: Morocco | J12: A | K12: =IF(D12=TemplateResults!D12,1,0)+IF(D13=TemplateResults!D13,1,0)+IF(D14=TemplateResults!D14,1,0) -> 1
B13: =F14 -> Bosnia | C13: 2 | D13: South Korea | E13: 2 | F13: Canada | G13: 2 | H13: Brazil | J13: B | K13: =IF(F12=TemplateResults!F12,1,0)+IF(F13=TemplateResults!F13,1,0)+IF(F14=TemplateResults!F14,1,0) -> 3
B14: =H14 -> Scotland | C14: 3 | D14: Czech Republic | E14: 3 | F14: Bosnia | G14: 3 | H14: Scotland | J14: C | K14: =IF(H12=TemplateResults!H12,1,0)+IF(H13=TemplateResults!H13,1,0)+IF(H14=TemplateResults!H14,1,0) -> 1
B15: =D18 -> Paraguay | C15: Group D | E15: Group E | G15: Group F | J15: D | K15: =IF(D16=TemplateResults!D16,1,0)+IF(D17=TemplateResults!D17,1,0)+IF(D18=TemplateResults!D18,1,0) -> 2
B16: =F18 -> Ivory Coast | C16: 1 | D16: United States | E16: 1 | F16: Germany | G16: 1 | H16: Netherlands | J16: E | K16: =IF(F16=TemplateResults!F16,1,0)+IF(F17=TemplateResults!F17,1,0)+IF(F18=TemplateResults!F18,1,0) -> 1
B17: =H18 -> Sweden | C17: 2 | D17: Turkey | E17: 2 | F17: Ecuador | G17: 2 | H17: Japan | J17: F | K17: =IF(H16=TemplateResults!H16,1,0)+IF(H17=TemplateResults!H17,1,0)+IF(H18=TemplateResults!H18,1,0) -> 3
B18: =D22 -> Egypt | C18: 3 | D18: Paraguay | E18: 3 | F18: Ivory Coast | G18: 3 | H18: Sweden | J18: G | K18: =IF(D20=TemplateResults!D20,1,0)+IF(D21=TemplateResults!D21,1,0)+IF(D22=TemplateResults!D22,1,0) -> 1 | M18: Round of 32 | Q18: Penalty | S18: Score
B19: =F22 -> Saudi Arabia | C19: Group G | E19: Group H | G19: Group I | J19: H | K19: =IF(F20=TemplateResults!F20,1,0)+IF(F21=TemplateResults!F21,1,0)+IF(F22=TemplateResults!F22,1,0) -> 1 | M19: Germany | N19: 2 | O19: 0 | P19: Paraguay | S19: =TemplateResults!$K$32*(IF(AND(N19<>O19,TemplateResults!N19<>TemplateResults!O19), IFS(AND(N19=TemplateResults!N19,O19=TemplateResults!O19),2,AND(N19>O19,TemplateResults!N19>TemplateResults!O19),1,AND(N19<O19,TemplateResults!N19<TemplateResults!O19),1,TRUE,0),0)+IF(AND(N19=O19,TemplateResults!N19=TemplateResults!O19),IF(N19=TemplateResults!N19,IFS(AND(Q19=TemplateResults!Q19,R19=TemplateResults!R19),3,AND(Q19>R19,TemplateResults!Q19>TemplateResults!R19),2,AND(Q19<R19,TemplateResults!Q19<TemplateResults!R19),2,TRUE,0.5),IFS(AND(Q19>R19,TemplateResults!Q19>TemplateResults!R19),1,AND(Q19<R19,TemplateResults!Q19<TemplateResults!R19),1,TRUE,0)),0)+IF(AND(N19<>O19,TemplateResults!N19=TemplateResults!O19),IFS(AND(N19>O19,TemplateResults!Q19>TemplateResults!R19),1,AND(N19<O19,TemplateResults!Q19<TemplateResults!R19),1,TRUE,0),0)+IF(AND(N19=O19,TemplateResults!N19<>TemplateResults!O19),IFS(AND(Q19>R19,TemplateResults!N19>TemplateResults!R19),1,AND(Q19<R19,TemplateResults!N19<TemplateResults!O19),1,TRUE,0),0)) -> 0
B20: =H22 -> Senegal | C20: 1 | D20: Belgium | E20: 1 | F20: Spain | G20: 1 | H20: France | J20: I | K20: =IF(H20=TemplateResults!H20,1,0)+IF(H21=TemplateResults!H21,1,0)+IF(H22=TemplateResults!H22,1,0) -> 3 | M20: France | N20: 3 | O20: 1 | P20: Sweden | S20: =TemplateResults!$K$32*(IF(AND(N20<>O20,TemplateResults!N20<>TemplateResults!O20), IFS(AND(N20=TemplateResults!N20,O20=TemplateResults!O20),2,AND(N20>O20,TemplateResults!N20>TemplateResults!O20),1,AND(N20<O20,TemplateResults!N20<TemplateResults!O20),1,TRUE,0),0)+IF(AND(N20=O20,TemplateResults!N20=TemplateResults!O20),IF(N20=TemplateResults!N20,IFS(AND(Q20=TemplateResults!Q20,R20=TemplateResults!R20),3,AND(Q20>R20,TemplateResults!Q20>TemplateResults!R20),2,AND(Q20<R20,TemplateResults!Q20<TemplateResults!R20),2,TRUE,0.5),IFS(AND(Q20>R20,TemplateResults!Q20>TemplateResults!R20),1,AND(Q20<R20,TemplateResults!Q20<TemplateResults!R20),1,TRUE,0)),0)+IF(AND(N20<>O20,TemplateResults!N20=TemplateResults!O20),IFS(AND(N20>O20,TemplateResults!Q20>TemplateResults!R20),1,AND(N20<O20,TemplateResults!Q20<TemplateResults!R20),1,TRUE,0),0)+IF(AND(N20=O20,TemplateResults!N20<>TemplateResults!O20),IFS(AND(Q20>R20,TemplateResults!N20>TemplateResults!R20),1,AND(Q20<R20,TemplateResults!N20<TemplateResults!O20),1,TRUE,0),0)) -> 4
B21: =D26 -> Algeria | C21: 2 | D21: Iran | E21: 2 | F21: Uruguay | G21: 2 | H21: Norway | J21: J | K21: =IF(D24=TemplateResults!D24,1,0)+IF(D25=TemplateResults!D25,1,0)+IF(D26=TemplateResults!D26,1,0) -> 3 | M21: South Africa | N21: 1 | O21: 2 | P21: Canada | S21: =TemplateResults!$K$32*(IF(AND(N21<>O21,TemplateResults!N21<>TemplateResults!O21), IFS(AND(N21=TemplateResults!N21,O21=TemplateResults!O21),2,AND(N21>O21,TemplateResults!N21>TemplateResults!O21),1,AND(N21<O21,TemplateResults!N21<TemplateResults!O21),1,TRUE,0),0)+IF(AND(N21=O21,TemplateResults!N21=TemplateResults!O21),IF(N21=TemplateResults!N21,IFS(AND(Q21=TemplateResults!Q21,R21=TemplateResults!R21),3,AND(Q21>R21,TemplateResults!Q21>TemplateResults!R21),2,AND(Q21<R21,TemplateResults!Q21<TemplateResults!R21),2,TRUE,0.5),IFS(AND(Q21>R21,TemplateResults!Q21>TemplateResults!R21),1,AND(Q21<R21,TemplateResults!Q21<TemplateResults!R21),1,TRUE,0)),0)+IF(AND(N21<>O21,TemplateResults!N21=TemplateResults!O21),IFS(AND(N21>O21,TemplateResults!Q21>TemplateResults!R21),1,AND(N21<O21,TemplateResults!Q21<TemplateResults!R21),1,TRUE,0),0)+IF(AND(N21=O21,TemplateResults!N21<>TemplateResults!O21),IFS(AND(Q21>R21,TemplateResults!N21>TemplateResults!R21),1,AND(Q21<R21,TemplateResults!N21<TemplateResults!O21),1,TRUE,0),0)) -> 4
B22: =F26 -> DR Congo | C22: 3 | D22: Egypt | E22: 3 | F22: Saudi Arabia | G22: 3 | H22: Senegal | J22: K | K22: =IF(F24=TemplateResults!F24,1,0)+IF(F25=TemplateResults!F25,1,0)+IF(F26=TemplateResults!F26,1,0) -> 1 | M22: Nederlands | N22: 2 | O22: 1 | P22: Morroco | S22: =TemplateResults!$K$32*(IF(AND(N22<>O22,TemplateResults!N22<>TemplateResults!O22), IFS(AND(N22=TemplateResults!N22,O22=TemplateResults!O22),2,AND(N22>O22,TemplateResults!N22>TemplateResults!O22),1,AND(N22<O22,TemplateResults!N22<TemplateResults!O22),1,TRUE,0),0)+IF(AND(N22=O22,TemplateResults!N22=TemplateResults!O22),IF(N22=TemplateResults!N22,IFS(AND(Q22=TemplateResults!Q22,R22=TemplateResults!R22),3,AND(Q22>R22,TemplateResults!Q22>TemplateResults!R22),2,AND(Q22<R22,TemplateResults!Q22<TemplateResults!R22),2,TRUE,0.5),IFS(AND(Q22>R22,TemplateResults!Q22>TemplateResults!R22),1,AND(Q22<R22,TemplateResults!Q22<TemplateResults!R22),1,TRUE,0)),0)+IF(AND(N22<>O22,TemplateResults!N22=TemplateResults!O22),IFS(AND(N22>O22,TemplateResults!Q22>TemplateResults!R22),1,AND(N22<O22,TemplateResults!Q22<TemplateResults!R22),1,TRUE,0),0)+IF(AND(N22=O22,TemplateResults!N22<>TemplateResults!O22),IFS(AND(Q22>R22,TemplateResults!N22>TemplateResults!R22),1,AND(Q22<R22,TemplateResults!N22<TemplateResults!O22),1,TRUE,0),0)) -> 0
B23: =H26 -> Ghana | C23: Group J | E23: Group K | G23: Group L | J23: L | K23: =IF(H24=TemplateResults!H24,1,0)+IF(H25=TemplateResults!H25,1,0)+IF(H26=TemplateResults!H26,1,0) -> 3 | M23: Portugal | N23: 1 | O23: 1 | P23: Croatia | Q23: 5 | R23: 4 | S23: =TemplateResults!$K$32*(IF(AND(N23<>O23,TemplateResults!N23<>TemplateResults!O23), IFS(AND(N23=TemplateResults!N23,O23=TemplateResults!O23),2,AND(N23>O23,TemplateResults!N23>TemplateResults!O23),1,AND(N23<O23,TemplateResults!N23<TemplateResults!O23),1,TRUE,0),0)+IF(AND(N23=O23,TemplateResults!N23=TemplateResults!O23),IF(N23=TemplateResults!N23,IFS(AND(Q23=TemplateResults!Q23,R23=TemplateResults!R23),3,AND(Q23>R23,TemplateResults!Q23>TemplateResults!R23),2,AND(Q23<R23,TemplateResults!Q23<TemplateResults!R23),2,TRUE,0.5),IFS(AND(Q23>R23,TemplateResults!Q23>TemplateResults!R23),1,AND(Q23<R23,TemplateResults!Q23<TemplateResults!R23),1,TRUE,0)),0)+IF(AND(N23<>O23,TemplateResults!N23=TemplateResults!O23),IFS(AND(N23>O23,TemplateResults!Q23>TemplateResults!R23),1,AND(N23<O23,TemplateResults!Q23<TemplateResults!R23),1,TRUE,0),0)+IF(AND(N23=O23,TemplateResults!N23<>TemplateResults!O23),IFS(AND(Q23>R23,TemplateResults!N23>TemplateResults!R23),1,AND(Q23<R23,TemplateResults!N23<TemplateResults!O23),1,TRUE,0),0)) -> 4
C24: 1 | D24: Argentina | E24: 1 | F24: Portugal | G24: 1 | H24: England | M24: Spain | N24: 2 | O24: 1 | P24: Austria | S24: =TemplateResults!$K$32*(IF(AND(N24<>O24,TemplateResults!N24<>TemplateResults!O24), IFS(AND(N24=TemplateResults!N24,O24=TemplateResults!O24),2,AND(N24>O24,TemplateResults!N24>TemplateResults!O24),1,AND(N24<O24,TemplateResults!N24<TemplateResults!O24),1,TRUE,0),0)+IF(AND(N24=O24,TemplateResults!N24=TemplateResults!O24),IF(N24=TemplateResults!N24,IFS(AND(Q24=TemplateResults!Q24,R24=TemplateResults!R24),3,AND(Q24>R24,TemplateResults!Q24>TemplateResults!R24),2,AND(Q24<R24,TemplateResults!Q24<TemplateResults!R24),2,TRUE,0.5),IFS(AND(Q24>R24,TemplateResults!Q24>TemplateResults!R24),1,AND(Q24<R24,TemplateResults!Q24<TemplateResults!R24),1,TRUE,0)),0)+IF(AND(N24<>O24,TemplateResults!N24=TemplateResults!O24),IFS(AND(N24>O24,TemplateResults!Q24>TemplateResults!R24),1,AND(N24<O24,TemplateResults!Q24<TemplateResults!R24),1,TRUE,0),0)+IF(AND(N24=O24,TemplateResults!N24<>TemplateResults!O24),IFS(AND(Q24>R24,TemplateResults!N24>TemplateResults!R24),1,AND(Q24<R24,TemplateResults!N24<TemplateResults!O24),1,TRUE,0),0)) -> 4
C25: 2 | D25: Austria | E25: 2 | F25: Colombia | G25: 2 | H25: Croatia | M25: United States | N25: 3 | O25: 0 | P25: Bosnia | S25: =TemplateResults!$K$32*(IF(AND(N25<>O25,TemplateResults!N25<>TemplateResults!O25), IFS(AND(N25=TemplateResults!N25,O25=TemplateResults!O25),2,AND(N25>O25,TemplateResults!N25>TemplateResults!O25),1,AND(N25<O25,TemplateResults!N25<TemplateResults!O25),1,TRUE,0),0)+IF(AND(N25=O25,TemplateResults!N25=TemplateResults!O25),IF(N25=TemplateResults!N25,IFS(AND(Q25=TemplateResults!Q25,R25=TemplateResults!R25),3,AND(Q25>R25,TemplateResults!Q25>TemplateResults!R25),2,AND(Q25<R25,TemplateResults!Q25<TemplateResults!R25),2,TRUE,0.5),IFS(AND(Q25>R25,TemplateResults!Q25>TemplateResults!R25),1,AND(Q25<R25,TemplateResults!Q25<TemplateResults!R25),1,TRUE,0)),0)+IF(AND(N25<>O25,TemplateResults!N25=TemplateResults!O25),IFS(AND(N25>O25,TemplateResults!Q25>TemplateResults!R25),1,AND(N25<O25,TemplateResults!Q25<TemplateResults!R25),1,TRUE,0),0)+IF(AND(N25=O25,TemplateResults!N25<>TemplateResults!O25),IFS(AND(Q25>R25,TemplateResults!N25>TemplateResults!R25),1,AND(Q25<R25,TemplateResults!N25<TemplateResults!O25),1,TRUE,0),0)) -> 4
C26: 3 | D26: Algeria | E26: 3 | F26: DR Congo | G26: 3 | H26: Ghana | M26: Belgium | N26: 2 | O26: 1 | P26: Senegal | S26: =TemplateResults!$K$32*(IF(AND(N26<>O26,TemplateResults!N26<>TemplateResults!O26), IFS(AND(N26=TemplateResults!N26,O26=TemplateResults!O26),2,AND(N26>O26,TemplateResults!N26>TemplateResults!O26),1,AND(N26<O26,TemplateResults!N26<TemplateResults!O26),1,TRUE,0),0)+IF(AND(N26=O26,TemplateResults!N26=TemplateResults!O26),IF(N26=TemplateResults!N26,IFS(AND(Q26=TemplateResults!Q26,R26=TemplateResults!R26),3,AND(Q26>R26,TemplateResults!Q26>TemplateResults!R26),2,AND(Q26<R26,TemplateResults!Q26<TemplateResults!R26),2,TRUE,0.5),IFS(AND(Q26>R26,TemplateResults!Q26>TemplateResults!R26),1,AND(Q26<R26,TemplateResults!Q26<TemplateResults!R26),1,TRUE,0)),0)+IF(AND(N26<>O26,TemplateResults!N26=TemplateResults!O26),IFS(AND(N26>O26,TemplateResults!Q26>TemplateResults!R26),1,AND(N26<O26,TemplateResults!Q26<TemplateResults!R26),1,TRUE,0),0)+IF(AND(N26=O26,TemplateResults!N26<>TemplateResults!O26),IFS(AND(Q26>R26,TemplateResults!N26>TemplateResults!R26),1,AND(Q26<R26,TemplateResults!N26<TemplateResults!O26),1,TRUE,0),0)) -> 4
C27: Best 3rd's | J27: Best 3rds | K27: {=SUMPRODUCT(COUNTIF({TemplateResults!D28:D30;TemplateResults!F28:F30;TemplateResults!H28:H29},{D28:D30;F28:F30;H28:H29}))} -> 5 | M27: Brazil | N27: 2 | O27: 2 | P27: Japan | Q27: 4 | R27: 5 | S27: =TemplateResults!$K$32*(IF(AND(N27<>O27,TemplateResults!N27<>TemplateResults!O27), IFS(AND(N27=TemplateResults!N27,O27=TemplateResults!O27),2,AND(N27>O27,TemplateResults!N27>TemplateResults!O27),1,AND(N27<O27,TemplateResults!N27<TemplateResults!O27),1,TRUE,0),0)+IF(AND(N27=O27,TemplateResults!N27=TemplateResults!O27),IF(N27=TemplateResults!N27,IFS(AND(Q27=TemplateResults!Q27,R27=TemplateResults!R27),3,AND(Q27>R27,TemplateResults!Q27>TemplateResults!R27),2,AND(Q27<R27,TemplateResults!Q27<TemplateResults!R27),2,TRUE,0.5),IFS(AND(Q27>R27,TemplateResults!Q27>TemplateResults!R27),1,AND(Q27<R27,TemplateResults!Q27<TemplateResults!R27),1,TRUE,0)),0)+IF(AND(N27<>O27,TemplateResults!N27=TemplateResults!O27),IFS(AND(N27>O27,TemplateResults!Q27>TemplateResults!R27),1,AND(N27<O27,TemplateResults!Q27<TemplateResults!R27),1,TRUE,0),0)+IF(AND(N27=O27,TemplateResults!N27<>TemplateResults!O27),IFS(AND(Q27>R27,TemplateResults!N27>TemplateResults!R27),1,AND(Q27<R27,TemplateResults!N27<TemplateResults!O27),1,TRUE,0),0)) -> 0
C28: 1 | D28: Czech Republic | E28: 4 | F28: Paraguay | G28: 7 | H28: Senegal | M28: Ivory Coast | N28: 1 | O28: 2 | P28: Norway | S28: =TemplateResults!$K$32*(IF(AND(N28<>O28,TemplateResults!N28<>TemplateResults!O28), IFS(AND(N28=TemplateResults!N28,O28=TemplateResults!O28),2,AND(N28>O28,TemplateResults!N28>TemplateResults!O28),1,AND(N28<O28,TemplateResults!N28<TemplateResults!O28),1,TRUE,0),0)+IF(AND(N28=O28,TemplateResults!N28=TemplateResults!O28),IF(N28=TemplateResults!N28,IFS(AND(Q28=TemplateResults!Q28,R28=TemplateResults!R28),3,AND(Q28>R28,TemplateResults!Q28>TemplateResults!R28),2,AND(Q28<R28,TemplateResults!Q28<TemplateResults!R28),2,TRUE,0.5),IFS(AND(Q28>R28,TemplateResults!Q28>TemplateResults!R28),1,AND(Q28<R28,TemplateResults!Q28<TemplateResults!R28),1,TRUE,0)),0)+IF(AND(N28<>O28,TemplateResults!N28=TemplateResults!O28),IFS(AND(N28>O28,TemplateResults!Q28>TemplateResults!R28),1,AND(N28<O28,TemplateResults!Q28<TemplateResults!R28),1,TRUE,0),0)+IF(AND(N28=O28,TemplateResults!N28<>TemplateResults!O28),IFS(AND(Q28>R28,TemplateResults!N28>TemplateResults!R28),1,AND(Q28<R28,TemplateResults!N28<TemplateResults!O28),1,TRUE,0),0)) -> 8
C29: 2 | D29: Bosnia | E29: 5 | F29: Ivory Coast | G29: 8 | H29: Algeria | M29: Mexico | N29: 1 | O29: 1 | P29: Ecuador | Q29: 4 | R29: 5 | S29: =TemplateResults!$K$32*(IF(AND(N29<>O29,TemplateResults!N29<>TemplateResults!O29), IFS(AND(N29=TemplateResults!N29,O29=TemplateResults!O29),2,AND(N29>O29,TemplateResults!N29>TemplateResults!O29),1,AND(N29<O29,TemplateResults!N29<TemplateResults!O29),1,TRUE,0),0)+IF(AND(N29=O29,TemplateResults!N29=TemplateResults!O29),IF(N29=TemplateResults!N29,IFS(AND(Q29=TemplateResults!Q29,R29=TemplateResults!R29),3,AND(Q29>R29,TemplateResults!Q29>TemplateResults!R29),2,AND(Q29<R29,TemplateResults!Q29<TemplateResults!R29),2,TRUE,0.5),IFS(AND(Q29>R29,TemplateResults!Q29>TemplateResults!R29),1,AND(Q29<R29,TemplateResults!Q29<TemplateResults!R29),1,TRUE,0)),0)+IF(AND(N29<>O29,TemplateResults!N29=TemplateResults!O29),IFS(AND(N29>O29,TemplateResults!Q29>TemplateResults!R29),1,AND(N29<O29,TemplateResults!Q29<TemplateResults!R29),1,TRUE,0),0)+IF(AND(N29=O29,TemplateResults!N29<>TemplateResults!O29),IFS(AND(Q29>R29,TemplateResults!N29>TemplateResults!R29),1,AND(Q29<R29,TemplateResults!N29<TemplateResults!O29),1,TRUE,0),0)) -> 0
C30: 3 | D30: Scotland | E30: 6 | F30: Sweden | M30: England | N30: 2 | O30: 1 | P30: DR Congo | S30: =TemplateResults!$K$32*(IF(AND(N30<>O30,TemplateResults!N30<>TemplateResults!O30), IFS(AND(N30=TemplateResults!N30,O30=TemplateResults!O30),2,AND(N30>O30,TemplateResults!N30>TemplateResults!O30),1,AND(N30<O30,TemplateResults!N30<TemplateResults!O30),1,TRUE,0),0)+IF(AND(N30=O30,TemplateResults!N30=TemplateResults!O30),IF(N30=TemplateResults!N30,IFS(AND(Q30=TemplateResults!Q30,R30=TemplateResults!R30),3,AND(Q30>R30,TemplateResults!Q30>TemplateResults!R30),2,AND(Q30<R30,TemplateResults!Q30<TemplateResults!R30),2,TRUE,0.5),IFS(AND(Q30>R30,TemplateResults!Q30>TemplateResults!R30),1,AND(Q30<R30,TemplateResults!Q30<TemplateResults!R30),1,TRUE,0)),0)+IF(AND(N30<>O30,TemplateResults!N30=TemplateResults!O30),IFS(AND(N30>O30,TemplateResults!Q30>TemplateResults!R30),1,AND(N30<O30,TemplateResults!Q30<TemplateResults!R30),1,TRUE,0),0)+IF(AND(N30=O30,TemplateResults!N30<>TemplateResults!O30),IFS(AND(Q30>R30,TemplateResults!N30>TemplateResults!R30),1,AND(Q30<R30,TemplateResults!N30<TemplateResults!O30),1,TRUE,0),0)) -> 8
J31: Total | K31: =sum(K12:K23,K27) -> 28 | M31: Argentina | N31: 4 | O31: 0 | P31: Cape Verde | S31: =TemplateResults!$K$32*(IF(AND(N31<>O31,TemplateResults!N31<>TemplateResults!O31), IFS(AND(N31=TemplateResults!N31,O31=TemplateResults!O31),2,AND(N31>O31,TemplateResults!N31>TemplateResults!O31),1,AND(N31<O31,TemplateResults!N31<TemplateResults!O31),1,TRUE,0),0)+IF(AND(N31=O31,TemplateResults!N31=TemplateResults!O31),IF(N31=TemplateResults!N31,IFS(AND(Q31=TemplateResults!Q31,R31=TemplateResults!R31),3,AND(Q31>R31,TemplateResults!Q31>TemplateResults!R31),2,AND(Q31<R31,TemplateResults!Q31<TemplateResults!R31),2,TRUE,0.5),IFS(AND(Q31>R31,TemplateResults!Q31>TemplateResults!R31),1,AND(Q31<R31,TemplateResults!Q31<TemplateResults!R31),1,TRUE,0)),0)+IF(AND(N31<>O31,TemplateResults!N31=TemplateResults!O31),IFS(AND(N31>O31,TemplateResults!Q31>TemplateResults!R31),1,AND(N31<O31,TemplateResults!Q31<TemplateResults!R31),1,TRUE,0),0)+IF(AND(N31=O31,TemplateResults!N31<>TemplateResults!O31),IFS(AND(Q31>R31,TemplateResults!N31>TemplateResults!R31),1,AND(Q31<R31,TemplateResults!N31<TemplateResults!O31),1,TRUE,0),0)) -> 4
M32: Australia | N32: 2 | O32: 1 | P32: Egypt | S32: =TemplateResults!$K$32*(IF(AND(N32<>O32,TemplateResults!N32<>TemplateResults!O32), IFS(AND(N32=TemplateResults!N32,O32=TemplateResults!O32),2,AND(N32>O32,TemplateResults!N32>TemplateResults!O32),1,AND(N32<O32,TemplateResults!N32<TemplateResults!O32),1,TRUE,0),0)+IF(AND(N32=O32,TemplateResults!N32=TemplateResults!O32),IF(N32=TemplateResults!N32,IFS(AND(Q32=TemplateResults!Q32,R32=TemplateResults!R32),3,AND(Q32>R32,TemplateResults!Q32>TemplateResults!R32),2,AND(Q32<R32,TemplateResults!Q32<TemplateResults!R32),2,TRUE,0.5),IFS(AND(Q32>R32,TemplateResults!Q32>TemplateResults!R32),1,AND(Q32<R32,TemplateResults!Q32<TemplateResults!R32),1,TRUE,0)),0)+IF(AND(N32<>O32,TemplateResults!N32=TemplateResults!O32),IFS(AND(N32>O32,TemplateResults!Q32>TemplateResults!R32),1,AND(N32<O32,TemplateResults!Q32<TemplateResults!R32),1,TRUE,0),0)+IF(AND(N32=O32,TemplateResults!N32<>TemplateResults!O32),IFS(AND(Q32>R32,TemplateResults!N32>TemplateResults!R32),1,AND(Q32<R32,TemplateResults!N32<TemplateResults!O32),1,TRUE,0),0)) -> 0
M33: Switzerland | N33: 2 | O33: 0 | P33: Algeria | S33: =TemplateResults!$K$32*(IF(AND(N33<>O33,TemplateResults!N33<>TemplateResults!O33), IFS(AND(N33=TemplateResults!N33,O33=TemplateResults!O33),2,AND(N33>O33,TemplateResults!N33>TemplateResults!O33),1,AND(N33<O33,TemplateResults!N33<TemplateResults!O33),1,TRUE,0),0)+IF(AND(N33=O33,TemplateResults!N33=TemplateResults!O33),IF(N33=TemplateResults!N33,IFS(AND(Q33=TemplateResults!Q33,R33=TemplateResults!R33),3,AND(Q33>R33,TemplateResults!Q33>TemplateResults!R33),2,AND(Q33<R33,TemplateResults!Q33<TemplateResults!R33),2,TRUE,0.5),IFS(AND(Q33>R33,TemplateResults!Q33>TemplateResults!R33),1,AND(Q33<R33,TemplateResults!Q33<TemplateResults!R33),1,TRUE,0)),0)+IF(AND(N33<>O33,TemplateResults!N33=TemplateResults!O33),IFS(AND(N33>O33,TemplateResults!Q33>TemplateResults!R33),1,AND(N33<O33,TemplateResults!Q33<TemplateResults!R33),1,TRUE,0),0)+IF(AND(N33=O33,TemplateResults!N33<>TemplateResults!O33),IFS(AND(Q33>R33,TemplateResults!N33>TemplateResults!R33),1,AND(Q33<R33,TemplateResults!N33<TemplateResults!O33),1,TRUE,0),0)) -> 8
M34: Colombia | N34: 0 | O34: 2 | P34: Ghana | S34: =TemplateResults!$K$32*(IF(AND(N34<>O34,TemplateResults!N34<>TemplateResults!O34), IFS(AND(N34=TemplateResults!N34,O34=TemplateResults!O34),2,AND(N34>O34,TemplateResults!N34>TemplateResults!O34),1,AND(N34<O34,TemplateResults!N34<TemplateResults!O34),1,TRUE,0),0)+IF(AND(N34=O34,TemplateResults!N34=TemplateResults!O34),IF(N34=TemplateResults!N34,IFS(AND(Q34=TemplateResults!Q34,R34=TemplateResults!R34),3,AND(Q34>R34,TemplateResults!Q34>TemplateResults!R34),2,AND(Q34<R34,TemplateResults!Q34<TemplateResults!R34),2,TRUE,0.5),IFS(AND(Q34>R34,TemplateResults!Q34>TemplateResults!R34),1,AND(Q34<R34,TemplateResults!Q34<TemplateResults!R34),1,TRUE,0)),0)+IF(AND(N34<>O34,TemplateResults!N34=TemplateResults!O34),IFS(AND(N34>O34,TemplateResults!Q34>TemplateResults!R34),1,AND(N34<O34,TemplateResults!Q34<TemplateResults!R34),1,TRUE,0),0)+IF(AND(N34=O34,TemplateResults!N34<>TemplateResults!O34),IFS(AND(Q34>R34,TemplateResults!N34>TemplateResults!R34),1,AND(Q34<R34,TemplateResults!N34<TemplateResults!O34),1,TRUE,0),0)) -> 0
M36: Bonus questions
M37: How many matches will go to extra time? | Q37: 5 - 8 | T37: =IF(Q37=TemplateResults!Q37,2,0) -> 2
M38: How many matches will be decided by penalties? | Q38: 0 - 4 | T38: =IF(Q38=TemplateResults!Q38,2,0) -> 2
M39: Which team will score the most goals? | Q39: Argentina | T39: =IF(Q39=TemplateResults!Q39,2,0) -> 0
M40: Total goals scored in the R-32 (no penalties) | Q40: 41 - 50 | T40: =IF(Q40=TemplateResults!Q40,2,0) -> 2
M41: Which team will score the fastest goal? | Q41: Argentina | T41: =IF(Q41=TemplateResults!Q41,2,0) -> 0
M42: Which team will score the latest goal (including extra time)? | Q42: Ecuador | T42: =IF(Q42=TemplateResults!Q42,2,0) -> 0
M43: Team with the biggest winning margin? | Q43: Argentina | T43: =IF(Q43="France",2,0)+IF(Q43="Spain",2,0) -> 0
...

Sheet Daniel
A2: Question | C2: Your answer | F2: Points
A3: 1 | B3: Name | C3: Daniel
A4: 2 | B4: Winner team | C4: Spain | F4: 10
A5: 3 | B5: Who wil be runner-up? | C5: Portugal | F5: 6
A6: 4 | B6: Favorite team (it's ok NOT to choose your own country) | C6: Argentina
A7: 5 | B7: Haw far will your favorite team go? | C7: Quarter final | F7: 4
A8: 6 | B8: Top scorer | C8: Mbappe | F8: 4
A9: 7 | B9: How far will Ecuador go in the cup? | C9: Quarter final | F9: 4
A11: Groups stage | C11: Group A | E11: Group B | G11: Group C | J11: Group | K11: Your score
B12: =D14 -> Czech Republic | C12: 1 | D12: Mexico | E12: 1 | F12: Switzerland | G12: 1 | H12: Brazil | J12: A | K12: =IF(D12=TemplateResults!D12,1,0)+IF(D13=TemplateResults!D13,1,0)+IF(D14=TemplateResults!D14,1,0) -> 1
B13: =F14 -> Bosnia | C13: 2 | D13: South Korea | E13: 2 | F13: Canada | G13: 2 | H13: Morocco | J13: B | K13: =IF(F12=TemplateResults!F12,1,0)+IF(F13=TemplateResults!F13,1,0)+IF(F14=TemplateResults!F14,1,0) -> 3
B14: =H14 -> Scotland | C14: 3 | D14: Czech Republic | E14: 3 | F14: Bosnia | G14: 3 | H14: Scotland | J14: C | K14: =IF(H12=TemplateResults!H12,1,0)+IF(H13=TemplateResults!H13,1,0)+IF(H14=TemplateResults!H14,1,0) -> 3
B15: =D18 -> Paraguay | C15: Group D | E15: Group E | G15: Group F | J15: D | K15: =IF(D16=TemplateResults!D16,1,0)+IF(D17=TemplateResults!D17,1,0)+IF(D18=TemplateResults!D18,1,0) -> 1
B16: =F18 -> Ivory Coast | C16: 1 | D16: Turkey | E16: 1 | F16: Germany | G16: 1 | H16: Netherlands | J16: E | K16: =IF(F16=TemplateResults!F16,1,0)+IF(F17=TemplateResults!F17,1,0)+IF(F18=TemplateResults!F18,1,0) -> 1
B17: =H18 -> Sweden | C17: 2 | D17: United States | E17: 2 | F17: Ecuador | G17: 2 | H17: Japan | J17: F | K17: =IF(H16=TemplateResults!H16,1,0)+IF(H17=TemplateResults!H17,1,0)+IF(H18=TemplateResults!H18,1,0) -> 3
B18: =D22 -> Iran | C18: 3 | D18: Paraguay | E18: 3 | F18: Ivory Coast | G18: 3 | H18: Sweden | J18: G | K18: =IF(D20=TemplateResults!D20,1,0)+IF(D21=TemplateResults!D21,1,0)+IF(D22=TemplateResults!D22,1,0) -> 3 | M18: Round of 32 | Q18: Penalty | S18: Score
B19: =F22 -> Saudi Arabia | C19: Group G | E19: Group H | G19: Group I | J19: H | K19: =IF(F20=TemplateResults!F20,1,0)+IF(F21=TemplateResults!F21,1,0)+IF(F22=TemplateResults!F22,1,0) -> 1 | M19: Germany | N19: 2 | O19: 0 | P19: Paraguay | S19: =TemplateResults!$K$32*(IF(AND(N19<>O19,TemplateResults!N19<>TemplateResults!O19), IFS(AND(N19=TemplateResults!N19,O19=TemplateResults!O19),2,AND(N19>O19,TemplateResults!N19>TemplateResults!O19),1,AND(N19<O19,TemplateResults!N19<TemplateResults!O19),1,TRUE,0),0)+IF(AND(N19=O19,TemplateResults!N19=TemplateResults!O19),IF(N19=TemplateResults!N19,IFS(AND(Q19=TemplateResults!Q19,R19=TemplateResults!R19),3,AND(Q19>R19,TemplateResults!Q19>TemplateResults!R19),2,AND(Q19<R19,TemplateResults!Q19<TemplateResults!R19),2,TRUE,0.5),IFS(AND(Q19>R19,TemplateResults!Q19>TemplateResults!R19),1,AND(Q19<R19,TemplateResults!Q19<TemplateResults!R19),1,TRUE,0)),0)+IF(AND(N19<>O19,TemplateResults!N19=TemplateResults!O19),IFS(AND(N19>O19,TemplateResults!Q19>TemplateResults!R19),1,AND(N19<O19,TemplateResults!Q19<TemplateResults!R19),1,TRUE,0),0)+IF(AND(N19=O19,TemplateResults!N19<>TemplateResults!O19),IFS(AND(Q19>R19,TemplateResults!N19>TemplateResults!R19),1,AND(Q19<R19,TemplateResults!N19<TemplateResults!O19),1,TRUE,0),0)) -> 0
B20: =H22 -> Senegal | C20: 1 | D20: Belgium | E20: 1 | F20: Spain | G20: 1 | H20: France | J20: I | K20: =IF(H20=TemplateResults!H20,1,0)+IF(H21=TemplateResults!H21,1,0)+IF(H22=TemplateResults!H22,1,0) -> 3 | M20: France | N20: 4 | O20: 1 | P20: Sweden | S20: =TemplateResults!$K$32*(IF(AND(N20<>O20,TemplateResults!N20<>TemplateResults!O20), IFS(AND(N20=TemplateResults!N20,O20=TemplateResults!O20),2,AND(N20>O20,TemplateResults!N20>TemplateResults!O20),1,AND(N20<O20,TemplateResults!N20<TemplateResults!O20),1,TRUE,0),0)+IF(AND(N20=O20,TemplateResults!N20=TemplateResults!O20),IF(N20=TemplateResults!N20,IFS(AND(Q20=TemplateResults!Q20,R20=TemplateResults!R20),3,AND(Q20>R20,TemplateResults!Q20>TemplateResults!R20),2,AND(Q20<R20,TemplateResults!Q20<TemplateResults!R20),2,TRUE,0.5),IFS(AND(Q20>R20,TemplateResults!Q20>TemplateResults!R20),1,AND(Q20<R20,TemplateResults!Q20<TemplateResults!R20),1,TRUE,0)),0)+IF(AND(N20<>O20,TemplateResults!N20=TemplateResults!O20),IFS(AND(N20>O20,TemplateResults!Q20>TemplateResults!R20),1,AND(N20<O20,TemplateResults!Q20<TemplateResults!R20),1,TRUE,0),0)+IF(AND(N20=O20,TemplateResults!N20<>TemplateResults!O20),IFS(AND(Q20>R20,TemplateResults!N20>TemplateResults!R20),1,AND(Q20<R20,TemplateResults!N20<TemplateResults!O20),1,TRUE,0),0)) -> 4
B21: =D26 -> Algeria | C21: 2 | D21: Egypt | E21: 2 | F21: Uruguay | G21: 2 | H21: Norway | J21: J | K21: =IF(D24=TemplateResults!D24,1,0)+IF(D25=TemplateResults!D25,1,0)+IF(D26=TemplateResults!D26,1,0) -> 3 | M21: South Africa | N21: 1 | O21: 1 | P21: Canada | Q21: 3 | R21: 5 | S21: =TemplateResults!$K$32*(IF(AND(N21<>O21,TemplateResults!N21<>TemplateResults!O21), IFS(AND(N21=TemplateResults!N21,O21=TemplateResults!O21),2,AND(N21>O21,TemplateResults!N21>TemplateResults!O21),1,AND(N21<O21,TemplateResults!N21<TemplateResults!O21),1,TRUE,0),0)+IF(AND(N21=O21,TemplateResults!N21=TemplateResults!O21),IF(N21=TemplateResults!N21,IFS(AND(Q21=TemplateResults!Q21,R21=TemplateResults!R21),3,AND(Q21>R21,TemplateResults!Q21>TemplateResults!R21),2,AND(Q21<R21,TemplateResults!Q21<TemplateResults!R21),2,TRUE,0.5),IFS(AND(Q21>R21,TemplateResults!Q21>TemplateResults!R21),1,AND(Q21<R21,TemplateResults!Q21<TemplateResults!R21),1,TRUE,0)),0)+IF(AND(N21<>O21,TemplateResults!N21=TemplateResults!O21),IFS(AND(N21>O21,TemplateResults!Q21>TemplateResults!R21),1,AND(N21<O21,TemplateResults!Q21<TemplateResults!R21),1,TRUE,0),0)+IF(AND(N21=O21,TemplateResults!N21<>TemplateResults!O21),IFS(AND(Q21>R21,TemplateResults!N21>TemplateResults!R21),1,AND(Q21<R21,TemplateResults!N21<TemplateResults!O21),1,TRUE,0),0)) -> 4
B22: =F26 -> Uzbekistan | C22: 3 | D22: Iran | E22: 3 | F22: Saudi Arabia | G22: 3 | H22: Senegal | J22: K | K22: =IF(F24=TemplateResults!F24,1,0)+IF(F25=TemplateResults!F25,1,0)+IF(F26=TemplateResults!F26,1,0) -> 0 | M22: Nederlands | N22: 2 | O22: 2 | P22: Morroco | Q22: 3 | R22: 4 | S22: =TemplateResults!$K$32*(IF(AND(N22<>O22,TemplateResults!N22<>TemplateResults!O22), IFS(AND(N22=TemplateResults!N22,O22=TemplateResults!O22),2,AND(N22>O22,TemplateResults!N22>TemplateResults!O22),1,AND(N22<O22,TemplateResults!N22<TemplateResults!O22),1,TRUE,0),0)+IF(AND(N22=O22,TemplateResults!N22=TemplateResults!O22),IF(N22=TemplateResults!N22,IFS(AND(Q22=TemplateResults!Q22,R22=TemplateResults!R22),3,AND(Q22>R22,TemplateResults!Q22>TemplateResults!R22),2,AND(Q22<R22,TemplateResults!Q22<TemplateResults!R22),2,TRUE,0.5),IFS(AND(Q22>R22,TemplateResults!Q22>TemplateResults!R22),1,AND(Q22<R22,TemplateResults!Q22<TemplateResults!R22),1,TRUE,0)),0)+IF(AND(N22<>O22,TemplateResults!N22=TemplateResults!O22),IFS(AND(N22>O22,TemplateResults!Q22>TemplateResults!R22),1,AND(N22<O22,TemplateResults!Q22<TemplateResults!R22),1,TRUE,0),0)+IF(AND(N22=O22,TemplateResults!N22<>TemplateResults!O22),IFS(AND(Q22>R22,TemplateResults!N22>TemplateResults!R22),1,AND(Q22<R22,TemplateResults!N22<TemplateResults!O22),1,TRUE,0),0)) -> 4
B23: =H26 -> Ghana | C23: Group J | E23: Group K | G23: Group L | J23: L | K23: =IF(H24=TemplateResults!H24,1,0)+IF(H25=TemplateResults!H25,1,0)+IF(H26=TemplateResults!H26,1,0) -> 3 | M23: Portugal | N23: 2 | O23: 1 | P23: Croatia | S23: =TemplateResults!$K$32*(IF(AND(N23<>O23,TemplateResults!N23<>TemplateResults!O23), IFS(AND(N23=TemplateResults!N23,O23=TemplateResults!O23),2,AND(N23>O23,TemplateResults!N23>TemplateResults!O23),1,AND(N23<O23,TemplateResults!N23<TemplateResults!O23),1,TRUE,0),0)+IF(AND(N23=O23,TemplateResults!N23=TemplateResults!O23),IF(N23=TemplateResults!N23,IFS(AND(Q23=TemplateResults!Q23,R23=TemplateResults!R23),3,AND(Q23>R23,TemplateResults!Q23>TemplateResults!R23),2,AND(Q23<R23,TemplateResults!Q23<TemplateResults!R23),2,TRUE,0.5),IFS(AND(Q23>R23,TemplateResults!Q23>TemplateResults!R23),1,AND(Q23<R23,TemplateResults!Q23<TemplateResults!R23),1,TRUE,0)),0)+IF(AND(N23<>O23,TemplateResults!N23=TemplateResults!O23),IFS(AND(N23>O23,TemplateResults!Q23>TemplateResults!R23),1,AND(N23<O23,TemplateResults!Q23<TemplateResults!R23),1,TRUE,0),0)+IF(AND(N23=O23,TemplateResults!N23<>TemplateResults!O23),IFS(AND(Q23>R23,TemplateResults!N23>TemplateResults!R23),1,AND(Q23<R23,TemplateResults!N23<TemplateResults!O23),1,TRUE,0),0)) -> 8
C24: 1 | D24: Argentina | E24: 1 | F24: Portugal | G24: 1 | H24: England | M24: Spain | N24: 2 | O24: 0 | P24: Austria | S24: =TemplateResults!$K$32*(IF(AND(N24<>O24,TemplateResults!N24<>TemplateResults!O24), IFS(AND(N24=TemplateResults!N24,O24=TemplateResults!O24),2,AND(N24>O24,TemplateResults!N24>TemplateResults!O24),1,AND(N24<O24,TemplateResults!N24<TemplateResults!O24),1,TRUE,0),0)+IF(AND(N24=O24,TemplateResults!N24=TemplateResults!O24),IF(N24=TemplateResults!N24,IFS(AND(Q24=TemplateResults!Q24,R24=TemplateResults!R24),3,AND(Q24>R24,TemplateResults!Q24>TemplateResults!R24),2,AND(Q24<R24,TemplateResults!Q24<TemplateResults!R24),2,TRUE,0.5),IFS(AND(Q24>R24,TemplateResults!Q24>TemplateResults!R24),1,AND(Q24<R24,TemplateResults!Q24<TemplateResults!R24),1,TRUE,0)),0)+IF(AND(N24<>O24,TemplateResults!N24=TemplateResults!O24),IFS(AND(N24>O24,TemplateResults!Q24>TemplateResults!R24),1,AND(N24<O24,TemplateResults!Q24<TemplateResults!R24),1,TRUE,0),0)+IF(AND(N24=O24,TemplateResults!N24<>TemplateResults!O24),IFS(AND(Q24>R24,TemplateResults!N24>TemplateResults!R24),1,AND(Q24<R24,TemplateResults!N24<TemplateResults!O24),1,TRUE,0),0)) -> 4
C25: 2 | D25: Austria | E25: 2 | F25: Colombia | G25: 2 | H25: Croatia | M25: United States | N25: 3 | O25: 1 | P25: Bosnia | S25: =TemplateResults!$K$32*(IF(AND(N25<>O25,TemplateResults!N25<>TemplateResults!O25), IFS(AND(N25=TemplateResults!N25,O25=TemplateResults!O25),2,AND(N25>O25,TemplateResults!N25>TemplateResults!O25),1,AND(N25<O25,TemplateResults!N25<TemplateResults!O25),1,TRUE,0),0)+IF(AND(N25=O25,TemplateResults!N25=TemplateResults!O25),IF(N25=TemplateResults!N25,IFS(AND(Q25=TemplateResults!Q25,R25=TemplateResults!R25),3,AND(Q25>R25,TemplateResults!Q25>TemplateResults!R25),2,AND(Q25<R25,TemplateResults!Q25<TemplateResults!R25),2,TRUE,0.5),IFS(AND(Q25>R25,TemplateResults!Q25>TemplateResults!R25),1,AND(Q25<R25,TemplateResults!Q25<TemplateResults!R25),1,TRUE,0)),0)+IF(AND(N25<>O25,TemplateResults!N25=TemplateResults!O25),IFS(AND(N25>O25,TemplateResults!Q25>TemplateResults!R25),1,AND(N25<O25,TemplateResults!Q25<TemplateResults!R25),1,TRUE,0),0)+IF(AND(N25=O25,TemplateResults!N25<>TemplateResults!O25),IFS(AND(Q25>R25,TemplateResults!N25>TemplateResults!R25),1,AND(Q25<R25,TemplateResults!N25<TemplateResults!O25),1,TRUE,0),0)) -> 4
C26: 3 | D26: Algeria | E26: 3 | F26: Uzbekistan | G26: 3 | H26: Ghana | M26: Belgium | N26: 2 | O26: 1 | P26: Senegal | S26: =TemplateResults!$K$32*(IF(AND(N26<>O26,TemplateResults!N26<>TemplateResults!O26), IFS(AND(N26=TemplateResults!N26,O26=TemplateResults!O26),2,AND(N26>O26,TemplateResults!N26>TemplateResults!O26),1,AND(N26<O26,TemplateResults!N26<TemplateResults!O26),1,TRUE,0),0)+IF(AND(N26=O26,TemplateResults!N26=TemplateResults!O26),IF(N26=TemplateResults!N26,IFS(AND(Q26=TemplateResults!Q26,R26=TemplateResults!R26),3,AND(Q26>R26,TemplateResults!Q26>TemplateResults!R26),2,AND(Q26<R26,TemplateResults!Q26<TemplateResults!R26),2,TRUE,0.5),IFS(AND(Q26>R26,TemplateResults!Q26>TemplateResults!R26),1,AND(Q26<R26,TemplateResults!Q26<TemplateResults!R26),1,TRUE,0)),0)+IF(AND(N26<>O26,TemplateResults!N26=TemplateResults!O26),IFS(AND(N26>O26,TemplateResults!Q26>TemplateResults!R26),1,AND(N26<O26,TemplateResults!Q26<TemplateResults!R26),1,TRUE,0),0)+IF(AND(N26=O26,TemplateResults!N26<>TemplateResults!O26),IFS(AND(Q26>R26,TemplateResults!N26>TemplateResults!R26),1,AND(Q26<R26,TemplateResults!N26<TemplateResults!O26),1,TRUE,0),0)) -> 4
C27: Best 3rd's | J27: Best 3rds | K27: {=SUMPRODUCT(COUNTIF({TemplateResults!D28:D30;TemplateResults!F28:F30;TemplateResults!H28:H29},{D28:D30;F28:F30;H28:H29}))} -> 5 | M27: Brazil | N27: 2 | O27: 1 | P27: Japan | S27: =TemplateResults!$K$32*(IF(AND(N27<>O27,TemplateResults!N27<>TemplateResults!O27), IFS(AND(N27=TemplateResults!N27,O27=TemplateResults!O27),2,AND(N27>O27,TemplateResults!N27>TemplateResults!O27),1,AND(N27<O27,TemplateResults!N27<TemplateResults!O27),1,TRUE,0),0)+IF(AND(N27=O27,TemplateResults!N27=TemplateResults!O27),IF(N27=TemplateResults!N27,IFS(AND(Q27=TemplateResults!Q27,R27=TemplateResults!R27),3,AND(Q27>R27,TemplateResults!Q27>TemplateResults!R27),2,AND(Q27<R27,TemplateResults!Q27<TemplateResults!R27),2,TRUE,0.5),IFS(AND(Q27>R27,TemplateResults!Q27>TemplateResults!R27),1,AND(Q27<R27,TemplateResults!Q27<TemplateResults!R27),1,TRUE,0)),0)+IF(AND(N27<>O27,TemplateResults!N27=TemplateResults!O27),IFS(AND(N27>O27,TemplateResults!Q27>TemplateResults!R27),1,AND(N27<O27,TemplateResults!Q27<TemplateResults!R27),1,TRUE,0),0)+IF(AND(N27=O27,TemplateResults!N27<>TemplateResults!O27),IFS(AND(Q27>R27,TemplateResults!N27>TemplateResults!R27),1,AND(Q27<R27,TemplateResults!N27<TemplateResults!O27),1,TRUE,0),0)) -> 8
C28: 1 | D28: Czech Republic | E28: 4 | F28: Sweden | G28: 7 | H28: Paraguay | M28: Ivory Coast | N28: 2 | O28: 2 | P28: Norway | Q28: 4 | R28: 5 | S28: =TemplateResults!$K$32*(IF(AND(N28<>O28,TemplateResults!N28<>TemplateResults!O28), IFS(AND(N28=TemplateResults!N28,O28=TemplateResults!O28),2,AND(N28>O28,TemplateResults!N28>TemplateResults!O28),1,AND(N28<O28,TemplateResults!N28<TemplateResults!O28),1,TRUE,0),0)+IF(AND(N28=O28,TemplateResults!N28=TemplateResults!O28),IF(N28=TemplateResults!N28,IFS(AND(Q28=TemplateResults!Q28,R28=TemplateResults!R28),3,AND(Q28>R28,TemplateResults!Q28>TemplateResults!R28),2,AND(Q28<R28,TemplateResults!Q28<TemplateResults!R28),2,TRUE,0.5),IFS(AND(Q28>R28,TemplateResults!Q28>TemplateResults!R28),1,AND(Q28<R28,TemplateResults!Q28<TemplateResults!R28),1,TRUE,0)),0)+IF(AND(N28<>O28,TemplateResults!N28=TemplateResults!O28),IFS(AND(N28>O28,TemplateResults!Q28>TemplateResults!R28),1,AND(N28<O28,TemplateResults!Q28<TemplateResults!R28),1,TRUE,0),0)+IF(AND(N28=O28,TemplateResults!N28<>TemplateResults!O28),IFS(AND(Q28>R28,TemplateResults!N28>TemplateResults!R28),1,AND(Q28<R28,TemplateResults!N28<TemplateResults!O28),1,TRUE,0),0)) -> 4
C29: 2 | D29: Scotland | E29: 5 | F29: Senegal | G29: 8 | H29: Bosnia | M29: Mexico | N29: 1 | O29: 1 | P29: Ecuador | Q29: 3 | R29: 4 | S29: =TemplateResults!$K$32*(IF(AND(N29<>O29,TemplateResults!N29<>TemplateResults!O29), IFS(AND(N29=TemplateResults!N29,O29=TemplateResults!O29),2,AND(N29>O29,TemplateResults!N29>TemplateResults!O29),1,AND(N29<O29,TemplateResults!N29<TemplateResults!O29),1,TRUE,0),0)+IF(AND(N29=O29,TemplateResults!N29=TemplateResults!O29),IF(N29=TemplateResults!N29,IFS(AND(Q29=TemplateResults!Q29,R29=TemplateResults!R29),3,AND(Q29>R29,TemplateResults!Q29>TemplateResults!R29),2,AND(Q29<R29,TemplateResults!Q29<TemplateResults!R29),2,TRUE,0.5),IFS(AND(Q29>R29,TemplateResults!Q29>TemplateResults!R29),1,AND(Q29<R29,TemplateResults!Q29<TemplateResults!R29),1,TRUE,0)),0)+IF(AND(N29<>O29,TemplateResults!N29=TemplateResults!O29),IFS(AND(N29>O29,TemplateResults!Q29>TemplateResults!R29),1,AND(N29<O29,TemplateResults!Q29<TemplateResults!R29),1,TRUE,0),0)+IF(AND(N29=O29,TemplateResults!N29<>TemplateResults!O29),IFS(AND(Q29>R29,TemplateResults!N29>TemplateResults!R29),1,AND(Q29<R29,TemplateResults!N29<TemplateResults!O29),1,TRUE,0),0)) -> 0
C30: 3 | D30: Ivory Coast | E30: 6 | F30: Ghana | M30: England | N30: 3 | O30: 1 | P30: DR Congo | S30: =TemplateResults!$K$32*(IF(AND(N30<>O30,TemplateResults!N30<>TemplateResults!O30), IFS(AND(N30=TemplateResults!N30,O30=TemplateResults!O30),2,AND(N30>O30,TemplateResults!N30>TemplateResults!O30),1,AND(N30<O30,TemplateResults!N30<TemplateResults!O30),1,TRUE,0),0)+IF(AND(N30=O30,TemplateResults!N30=TemplateResults!O30),IF(N30=TemplateResults!N30,IFS(AND(Q30=TemplateResults!Q30,R30=TemplateResults!R30),3,AND(Q30>R30,TemplateResults!Q30>TemplateResults!R30),2,AND(Q30<R30,TemplateResults!Q30<TemplateResults!R30),2,TRUE,0.5),IFS(AND(Q30>R30,TemplateResults!Q30>TemplateResults!R30),1,AND(Q30<R30,TemplateResults!Q30<TemplateResults!R30),1,TRUE,0)),0)+IF(AND(N30<>O30,TemplateResults!N30=TemplateResults!O30),IFS(AND(N30>O30,TemplateResults!Q30>TemplateResults!R30),1,AND(N30<O30,TemplateResults!Q30<TemplateResults!R30),1,TRUE,0),0)+IF(AND(N30=O30,TemplateResults!N30<>TemplateResults!O30),IFS(AND(Q30>R30,TemplateResults!N30>TemplateResults!R30),1,AND(Q30<R30,TemplateResults!N30<TemplateResults!O30),1,TRUE,0),0)) -> 4
J31: Total | K31: =sum(K12:K23,K27) -> 30 | M31: Argentina | N31: 3 | O31: 0 | P31: Cape Verde | S31: =TemplateResults!$K$32*(IF(AND(N31<>O31,TemplateResults!N31<>TemplateResults!O31), IFS(AND(N31=TemplateResults!N31,O31=TemplateResults!O31),2,AND(N31>O31,TemplateResults!N31>TemplateResults!O31),1,AND(N31<O31,TemplateResults!N31<TemplateResults!O31),1,TRUE,0),0)+IF(AND(N31=O31,TemplateResults!N31=TemplateResults!O31),IF(N31=TemplateResults!N31,IFS(AND(Q31=TemplateResults!Q31,R31=TemplateResults!R31),3,AND(Q31>R31,TemplateResults!Q31>TemplateResults!R31),2,AND(Q31<R31,TemplateResults!Q31<TemplateResults!R31),2,TRUE,0.5),IFS(AND(Q31>R31,TemplateResults!Q31>TemplateResults!R31),1,AND(Q31<R31,TemplateResults!Q31<TemplateResults!R31),1,TRUE,0)),0)+IF(AND(N31<>O31,TemplateResults!N31=TemplateResults!O31),IFS(AND(N31>O31,TemplateResults!Q31>TemplateResults!R31),1,AND(N31<O31,TemplateResults!Q31<TemplateResults!R31),1,TRUE,0),0)+IF(AND(N31=O31,TemplateResults!N31<>TemplateResults!O31),IFS(AND(Q31>R31,TemplateResults!N31>TemplateResults!R31),1,AND(Q31<R31,TemplateResults!N31<TemplateResults!O31),1,TRUE,0),0)) -> 4
M32: Australia | N32: 1 | O32: 1 | P32: Egypt | Q32: 3 | R32: 4 | S32: =TemplateResults!$K$32*(IF(AND(N32<>O32,TemplateResults!N32<>TemplateResults!O32), IFS(AND(N32=TemplateResults!N32,O32=TemplateResults!O32),2,AND(N32>O32,TemplateResults!N32>TemplateResults!O32),1,AND(N32<O32,TemplateResults!N32<TemplateResults!O32),1,TRUE,0),0)+IF(AND(N32=O32,TemplateResults!N32=TemplateResults!O32),IF(N32=TemplateResults!N32,IFS(AND(Q32=TemplateResults!Q32,R32=TemplateResults!R32),3,AND(Q32>R32,TemplateResults!Q32>TemplateResults!R32),2,AND(Q32<R32,TemplateResults!Q32<TemplateResults!R32),2,TRUE,0.5),IFS(AND(Q32>R32,TemplateResults!Q32>TemplateResults!R32),1,AND(Q32<R32,TemplateResults!Q32<TemplateResults!R32),1,TRUE,0)),0)+IF(AND(N32<>O32,TemplateResults!N32=TemplateResults!O32),IFS(AND(N32>O32,TemplateResults!Q32>TemplateResults!R32),1,AND(N32<O32,TemplateResults!Q32<TemplateResults!R32),1,TRUE,0),0)+IF(AND(N32=O32,TemplateResults!N32<>TemplateResults!O32),IFS(AND(Q32>R32,TemplateResults!N32>TemplateResults!R32),1,AND(Q32<R32,TemplateResults!N32<TemplateResults!O32),1,TRUE,0),0)) -> 8
M33: Switzerland | N33: 2 | O33: 1 | P33: Algeria | S33: =TemplateResults!$K$32*(IF(AND(N33<>O33,TemplateResults!N33<>TemplateResults!O33), IFS(AND(N33=TemplateResults!N33,O33=TemplateResults!O33),2,AND(N33>O33,TemplateResults!N33>TemplateResults!O33),1,AND(N33<O33,TemplateResults!N33<TemplateResults!O33),1,TRUE,0),0)+IF(AND(N33=O33,TemplateResults!N33=TemplateResults!O33),IF(N33=TemplateResults!N33,IFS(AND(Q33=TemplateResults!Q33,R33=TemplateResults!R33),3,AND(Q33>R33,TemplateResults!Q33>TemplateResults!R33),2,AND(Q33<R33,TemplateResults!Q33<TemplateResults!R33),2,TRUE,0.5),IFS(AND(Q33>R33,TemplateResults!Q33>TemplateResults!R33),1,AND(Q33<R33,TemplateResults!Q33<TemplateResults!R33),1,TRUE,0)),0)+IF(AND(N33<>O33,TemplateResults!N33=TemplateResults!O33),IFS(AND(N33>O33,TemplateResults!Q33>TemplateResults!R33),1,AND(N33<O33,TemplateResults!Q33<TemplateResults!R33),1,TRUE,0),0)+IF(AND(N33=O33,TemplateResults!N33<>TemplateResults!O33),IFS(AND(Q33>R33,TemplateResults!N33>TemplateResults!R33),1,AND(Q33<R33,TemplateResults!N33<TemplateResults!O33),1,TRUE,0),0)) -> 4
M34: Colombia | N34: 2 | O34: 1 | P34: Ghana | S34: =TemplateResults!$K$32*(IF(AND(N34<>O34,TemplateResults!N34<>TemplateResults!O34), IFS(AND(N34=TemplateResults!N34,O34=TemplateResults!O34),2,AND(N34>O34,TemplateResults!N34>TemplateResults!O34),1,AND(N34<O34,TemplateResults!N34<TemplateResults!O34),1,TRUE,0),0)+IF(AND(N34=O34,TemplateResults!N34=TemplateResults!O34),IF(N34=TemplateResults!N34,IFS(AND(Q34=TemplateResults!Q34,R34=TemplateResults!R34),3,AND(Q34>R34,TemplateResults!Q34>TemplateResults!R34),2,AND(Q34<R34,TemplateResults!Q34<TemplateResults!R34),2,TRUE,0.5),IFS(AND(Q34>R34,TemplateResults!Q34>TemplateResults!R34),1,AND(Q34<R34,TemplateResults!Q34<TemplateResults!R34),1,TRUE,0)),0)+IF(AND(N34<>O34,TemplateResults!N34=TemplateResults!O34),IFS(AND(N34>O34,TemplateResults!Q34>TemplateResults!R34),1,AND(N34<O34,TemplateResults!Q34<TemplateResults!R34),1,TRUE,0),0)+IF(AND(N34=O34,TemplateResults!N34<>TemplateResults!O34),IFS(AND(Q34>R34,TemplateResults!N34>TemplateResults!R34),1,AND(Q34<R34,TemplateResults!N34<TemplateResults!O34),1,TRUE,0),0)) -> 4
M36: Bonus questions
M37: How many matches will go to extra time? | Q37: 5 - 8 | T37: =IF(Q37=TemplateResults!Q37,2,0) -> 2
M38: How many matches will be decided by penalties? | Q38: 5 - 8 | T38: =IF(Q38=TemplateResults!Q38,2,0) -> 0
M39: Which team will score the most goals? | Q39: France | T39: =IF(Q39=TemplateResults!Q39,2,0) -> 0
M40: Total goals scored in the R-32 (no penalties) | Q40: 41 - 50 | T40: =IF(Q40=TemplateResults!Q40,2,0) -> 2
M41: Which team will score the fastest goal? | Q41: Germany | T41: =IF(Q41=TemplateResults!Q41,2,0) -> 0
M42: Which team will score the latest goal (including extra time)? | Q42: Portugal | T42: =IF(Q42=TemplateResults!Q42,2,0) -> 0
M43: Team with the biggest winning margin? | Q43: Argentina | T43: =IF(Q43="France",2,0)+IF(Q43="Spain",2,0) -> 0
...

Sheet jjpro
A2: Question | C2: Your answer | F2: Points
A3: 1 | B3: Name | C3: Juan
A4: 2 | B4: Winner team | C4: Portugal | F4: 10
A5: 3 | B5: Who wil be runner-up? | C5: Spain | F5: 6
A6: 4 | B6: Favorite team (it's ok NOT to choose your own country) | C6: England
A7: 5 | B7: Haw far will your favorite team go? | C7: Semi final | F7: 4
A8: 6 | B8: Top scorer | C8: Kylian Mbappe | F8: 4
A9: 7 | B9: How far will Ecuador go in the cup? | C9: Quarter final | F9: 4
A11: Groups stage | C11: Group A | E11: Group B | G11: Group C | J11: Group | K11: Your score
B12: =D14 -> South Korea | C12: 1 | D12: Mexico | E12: 1 | F12: Canada | G12: 1 | H12: Brazil | J12: A | K12: =IF(D12=TemplateResults!D12,1,0)+IF(D13=TemplateResults!D13,1,0)+IF(D14=TemplateResults!D14,1,0) -> 2
B13: =F14 -> Bosnia | C13: 2 | D13: Czech Republic | E13: 2 | F13: Switzerland | G13: 2 | H13: Morocco | J13: B | K13: =IF(F12=TemplateResults!F12,1,0)+IF(F13=TemplateResults!F13,1,0)+IF(F14=TemplateResults!F14,1,0) -> 1
B14: =H14 -> Haiti | C14: 3 | D14: South Korea | E14: 3 | F14: Bosnia | G14: 3 | H14: Haiti | J14: C | K14: =IF(H12=TemplateResults!H12,1,0)+IF(H13=TemplateResults!H13,1,0)+IF(H14=TemplateResults!H14,1,0) -> 2
B15: =D18 -> Paraguay | C15: Group D | E15: Group E | G15: Group F | J15: D | K15: =IF(D16=TemplateResults!D16,1,0)+IF(D17=TemplateResults!D17,1,0)+IF(D18=TemplateResults!D18,1,0) -> 1
B16: =F18 -> Ivory Coast | C16: 1 | D16: Turkey | E16: 1 | F16: Ecuador | G16: 1 | H16: Netherlands | J16: E | K16: =IF(F16=TemplateResults!F16,1,0)+IF(F17=TemplateResults!F17,1,0)+IF(F18=TemplateResults!F18,1,0) -> 0
B17: =H18 -> Japan | C17: 2 | D17: United States | E17: 2 | F17: Germany | G17: 2 | H17: Sweden | J17: F | K17: =IF(H16=TemplateResults!H16,1,0)+IF(H17=TemplateResults!H17,1,0)+IF(H18=TemplateResults!H18,1,0) -> 1
B18: =D22 -> Iran | C18: 3 | D18: Paraguay | E18: 3 | F18: Ivory Coast | G18: 3 | H18: Japan | J18: G | K18: =IF(D20=TemplateResults!D20,1,0)+IF(D21=TemplateResults!D21,1,0)+IF(D22=TemplateResults!D22,1,0) -> 3 | M18: Round of 32 | Q18: Penalty | S18: Score
B19: =F22 -> Saudi Arabia | C19: Group G | E19: Group H | G19: Group I | J19: H | K19: =IF(F20=TemplateResults!F20,1,0)+IF(F21=TemplateResults!F21,1,0)+IF(F22=TemplateResults!F22,1,0) -> 1 | M19: Germany | N19: 3 | O19: 1 | P19: Paraguay | S19: =TemplateResults!$K$32*(IF(AND(N19<>O19,TemplateResults!N19<>TemplateResults!O19), IFS(AND(N19=TemplateResults!N19,O19=TemplateResults!O19),2,AND(N19>O19,TemplateResults!N19>TemplateResults!O19),1,AND(N19<O19,TemplateResults!N19<TemplateResults!O19),1,TRUE,0),0)+IF(AND(N19=O19,TemplateResults!N19=TemplateResults!O19),IF(N19=TemplateResults!N19,IFS(AND(Q19=TemplateResults!Q19,R19=TemplateResults!R19),3,AND(Q19>R19,TemplateResults!Q19>TemplateResults!R19),2,AND(Q19<R19,TemplateResults!Q19<TemplateResults!R19),2,TRUE,0.5),IFS(AND(Q19>R19,TemplateResults!Q19>TemplateResults!R19),1,AND(Q19<R19,TemplateResults!Q19<TemplateResults!R19),1,TRUE,0)),0)+IF(AND(N19<>O19,TemplateResults!N19=TemplateResults!O19),IFS(AND(N19>O19,TemplateResults!Q19>TemplateResults!R19),1,AND(N19<O19,TemplateResults!Q19<TemplateResults!R19),1,TRUE,0),0)+IF(AND(N19=O19,TemplateResults!N19<>TemplateResults!O19),IFS(AND(Q19>R19,TemplateResults!N19>TemplateResults!R19),1,AND(Q19<R19,TemplateResults!N19<TemplateResults!O19),1,TRUE,0),0)) -> 0
B20: =H22 -> Senegal | C20: 1 | D20: Belgium | E20: 1 | F20: Spain | G20: 1 | H20: France | J20: I | K20: =IF(H20=TemplateResults!H20,1,0)+IF(H21=TemplateResults!H21,1,0)+IF(H22=TemplateResults!H22,1,0) -> 3 | M20: France | N20: 4 | O20: 1 | P20: Sweden | S20: =TemplateResults!$K$32*(IF(AND(N20<>O20,TemplateResults!N20<>TemplateResults!O20), IFS(AND(N20=TemplateResults!N20,O20=TemplateResults!O20),2,AND(N20>O20,TemplateResults!N20>TemplateResults!O20),1,AND(N20<O20,TemplateResults!N20<TemplateResults!O20),1,TRUE,0),0)+IF(AND(N20=O20,TemplateResults!N20=TemplateResults!O20),IF(N20=TemplateResults!N20,IFS(AND(Q20=TemplateResults!Q20,R20=TemplateResults!R20),3,AND(Q20>R20,TemplateResults!Q20>TemplateResults!R20),2,AND(Q20<R20,TemplateResults!Q20<TemplateResults!R20),2,TRUE,0.5),IFS(AND(Q20>R20,TemplateResults!Q20>TemplateResults!R20),1,AND(Q20<R20,TemplateResults!Q20<TemplateResults!R20),1,TRUE,0)),0)+IF(AND(N20<>O20,TemplateResults!N20=TemplateResults!O20),IFS(AND(N20>O20,TemplateResults!Q20>TemplateResults!R20),1,AND(N20<O20,TemplateResults!Q20<TemplateResults!R20),1,TRUE,0),0)+IF(AND(N20=O20,TemplateResults!N20<>TemplateResults!O20),IFS(AND(Q20>R20,TemplateResults!N20>TemplateResults!R20),1,AND(Q20<R20,TemplateResults!N20<TemplateResults!O20),1,TRUE,0),0)) -> 4
B21: =D26 -> Algeria | C21: 2 | D21: Egypt | E21: 2 | F21: Uruguay | G21: 2 | H21: Norway | J21: J | K21: =IF(D24=TemplateResults!D24,1,0)+IF(D25=TemplateResults!D25,1,0)+IF(D26=TemplateResults!D26,1,0) -> 3 | M21: South Africa | N21: 0 | O21: 2 | P21: Canada | S21: =TemplateResults!$K$32*(IF(AND(N21<>O21,TemplateResults!N21<>TemplateResults!O21), IFS(AND(N21=TemplateResults!N21,O21=TemplateResults!O21),2,AND(N21>O21,TemplateResults!N21>TemplateResults!O21),1,AND(N21<O21,TemplateResults!N21<TemplateResults!O21),1,TRUE,0),0)+IF(AND(N21=O21,TemplateResults!N21=TemplateResults!O21),IF(N21=TemplateResults!N21,IFS(AND(Q21=TemplateResults!Q21,R21=TemplateResults!R21),3,AND(Q21>R21,TemplateResults!Q21>TemplateResults!R21),2,AND(Q21<R21,TemplateResults!Q21<TemplateResults!R21),2,TRUE,0.5),IFS(AND(Q21>R21,TemplateResults!Q21>TemplateResults!R21),1,AND(Q21<R21,TemplateResults!Q21<TemplateResults!R21),1,TRUE,0)),0)+IF(AND(N21<>O21,TemplateResults!N21=TemplateResults!O21),IFS(AND(N21>O21,TemplateResults!Q21>TemplateResults!R21),1,AND(N21<O21,TemplateResults!Q21<TemplateResults!R21),1,TRUE,0),0)+IF(AND(N21=O21,TemplateResults!N21<>TemplateResults!O21),IFS(AND(Q21>R21,TemplateResults!N21>TemplateResults!R21),1,AND(Q21<R21,TemplateResults!N21<TemplateResults!O21),1,TRUE,0),0)) -> 4
B22: =F26 -> Uzbekistan | C22: 3 | D22: Iran | E22: 3 | F22: Saudi Arabia | G22: 3 | H22: Senegal | J22: K | K22: =IF(F24=TemplateResults!F24,1,0)+IF(F25=TemplateResults!F25,1,0)+IF(F26=TemplateResults!F26,1,0) -> 0 | M22: Nederlands | N22: 2 | O22: 1 | P22: Morroco | S22: =TemplateResults!$K$32*(IF(AND(N22<>O22,TemplateResults!N22<>TemplateResults!O22), IFS(AND(N22=TemplateResults!N22,O22=TemplateResults!O22),2,AND(N22>O22,TemplateResults!N22>TemplateResults!O22),1,AND(N22<O22,TemplateResults!N22<TemplateResults!O22),1,TRUE,0),0)+IF(AND(N22=O22,TemplateResults!N22=TemplateResults!O22),IF(N22=TemplateResults!N22,IFS(AND(Q22=TemplateResults!Q22,R22=TemplateResults!R22),3,AND(Q22>R22,TemplateResults!Q22>TemplateResults!R22),2,AND(Q22<R22,TemplateResults!Q22<TemplateResults!R22),2,TRUE,0.5),IFS(AND(Q22>R22,TemplateResults!Q22>TemplateResults!R22),1,AND(Q22<R22,TemplateResults!Q22<TemplateResults!R22),1,TRUE,0)),0)+IF(AND(N22<>O22,TemplateResults!N22=TemplateResults!O22),IFS(AND(N22>O22,TemplateResults!Q22>TemplateResults!R22),1,AND(N22<O22,TemplateResults!Q22<TemplateResults!R22),1,TRUE,0),0)+IF(AND(N22=O22,TemplateResults!N22<>TemplateResults!O22),IFS(AND(Q22>R22,TemplateResults!N22>TemplateResults!R22),1,AND(Q22<R22,TemplateResults!N22<TemplateResults!O22),1,TRUE,0),0)) -> 0
B23: =H26 -> Ghana | C23: Group J | E23: Group K | G23: Group L | J23: L | K23: =IF(H24=TemplateResults!H24,1,0)+IF(H25=TemplateResults!H25,1,0)+IF(H26=TemplateResults!H26,1,0) -> 3 | M23: Portugal | N23: 2 | O23: 1 | P23: Croatia | S23: =TemplateResults!$K$32*(IF(AND(N23<>O23,TemplateResults!N23<>TemplateResults!O23), IFS(AND(N23=TemplateResults!N23,O23=TemplateResults!O23),2,AND(N23>O23,TemplateResults!N23>TemplateResults!O23),1,AND(N23<O23,TemplateResults!N23<TemplateResults!O23),1,TRUE,0),0)+IF(AND(N23=O23,TemplateResults!N23=TemplateResults!O23),IF(N23=TemplateResults!N23,IFS(AND(Q23=TemplateResults!Q23,R23=TemplateResults!R23),3,AND(Q23>R23,TemplateResults!Q23>TemplateResults!R23),2,AND(Q23<R23,TemplateResults!Q23<TemplateResults!R23),2,TRUE,0.5),IFS(AND(Q23>R23,TemplateResults!Q23>TemplateResults!R23),1,AND(Q23<R23,TemplateResults!Q23<TemplateResults!R23),1,TRUE,0)),0)+IF(AND(N23<>O23,TemplateResults!N23=TemplateResults!O23),IFS(AND(N23>O23,TemplateResults!Q23>TemplateResults!R23),1,AND(N23<O23,TemplateResults!Q23<TemplateResults!R23),1,TRUE,0),0)+IF(AND(N23=O23,TemplateResults!N23<>TemplateResults!O23),IFS(AND(Q23>R23,TemplateResults!N23>TemplateResults!R23),1,AND(Q23<R23,TemplateResults!N23<TemplateResults!O23),1,TRUE,0),0)) -> 8
C24: 1 | D24: Argentina | E24: 1 | F24: Portugal | G24: 1 | H24: England | M24: Spain | N24: 2 | O24: 0 | P24: Austria | S24: =TemplateResults!$K$32*(IF(AND(N24<>O24,TemplateResults!N24<>TemplateResults!O24), IFS(AND(N24=TemplateResults!N24,O24=TemplateResults!O24),2,AND(N24>O24,TemplateResults!N24>TemplateResults!O24),1,AND(N24<O24,TemplateResults!N24<TemplateResults!O24),1,TRUE,0),0)+IF(AND(N24=O24,TemplateResults!N24=TemplateResults!O24),IF(N24=TemplateResults!N24,IFS(AND(Q24=TemplateResults!Q24,R24=TemplateResults!R24),3,AND(Q24>R24,TemplateResults!Q24>TemplateResults!R24),2,AND(Q24<R24,TemplateResults!Q24<TemplateResults!R24),2,TRUE,0.5),IFS(AND(Q24>R24,TemplateResults!Q24>TemplateResults!R24),1,AND(Q24<R24,TemplateResults!Q24<TemplateResults!R24),1,TRUE,0)),0)+IF(AND(N24<>O24,TemplateResults!N24=TemplateResults!O24),IFS(AND(N24>O24,TemplateResults!Q24>TemplateResults!R24),1,AND(N24<O24,TemplateResults!Q24<TemplateResults!R24),1,TRUE,0),0)+IF(AND(N24=O24,TemplateResults!N24<>TemplateResults!O24),IFS(AND(Q24>R24,TemplateResults!N24>TemplateResults!R24),1,AND(Q24<R24,TemplateResults!N24<TemplateResults!O24),1,TRUE,0),0)) -> 4
C25: 2 | D25: Austria | E25: 2 | F25: Colombia | G25: 2 | H25: Croatia | M25: United States | N25: 3 | O25: 0 | P25: Bosnia | S25: =TemplateResults!$K$32*(IF(AND(N25<>O25,TemplateResults!N25<>TemplateResults!O25), IFS(AND(N25=TemplateResults!N25,O25=TemplateResults!O25),2,AND(N25>O25,TemplateResults!N25>TemplateResults!O25),1,AND(N25<O25,TemplateResults!N25<TemplateResults!O25),1,TRUE,0),0)+IF(AND(N25=O25,TemplateResults!N25=TemplateResults!O25),IF(N25=TemplateResults!N25,IFS(AND(Q25=TemplateResults!Q25,R25=TemplateResults!R25),3,AND(Q25>R25,TemplateResults!Q25>TemplateResults!R25),2,AND(Q25<R25,TemplateResults!Q25<TemplateResults!R25),2,TRUE,0.5),IFS(AND(Q25>R25,TemplateResults!Q25>TemplateResults!R25),1,AND(Q25<R25,TemplateResults!Q25<TemplateResults!R25),1,TRUE,0)),0)+IF(AND(N25<>O25,TemplateResults!N25=TemplateResults!O25),IFS(AND(N25>O25,TemplateResults!Q25>TemplateResults!R25),1,AND(N25<O25,TemplateResults!Q25<TemplateResults!R25),1,TRUE,0),0)+IF(AND(N25=O25,TemplateResults!N25<>TemplateResults!O25),IFS(AND(Q25>R25,TemplateResults!N25>TemplateResults!R25),1,AND(Q25<R25,TemplateResults!N25<TemplateResults!O25),1,TRUE,0),0)) -> 4
